<?xml version="1.0" encoding="utf-8"?>
<!-- This URDF was automatically created by SolidWorks to URDF Exporter! Originally created by Stephen Brawner (brawner@gmail.com) 
     Commit Version: 1.6.0-4-g7f85cfe  Build Version: 1.6.7995.38578
     For more information, please see http://wiki.ros.org/sw_urdf_exporter -->
<robot
  name="robotuv">

  <link name="base_footprint"/>

  <joint name="base_joint" type="fixed">
    <parent link="base_footprint"/>
    <child link="base_link"/>
    <origin xyz="0.45661 0.0 0.249" rpy="0 0 0"/>
  </joint>

  <link
    name="base_link">
    <inertial>
      <origin
        xyz="0 0 0"
        rpy="0 0 0" />
      <mass
        value="1.55786589047036" />
      <inertia
        ixx="0.0841848024339523"
        ixy="-0.000125051767145333"
        ixz="-0.00161954165264875"
        iyy="0.0938388928064463"
        iyz="-0.00013190022083076"
        izz="0.0461862484489722" />
    </inertial>
    <visual>
      <origin
        xyz="0 0 0"
        rpy="0 0 0" />
      <geometry>
        <mesh
          filename="package://robotuv/meshes/base_link.STL" />
      </geometry>
      <material
        name="">
        <color
          rgba="0.792156862745098 0.819607843137255 0.933333333333333 1" />
      </material>
    </visual>
    <collision>
      <origin
        xyz="0 0 0"
        rpy="0 0 0" />
      <geometry>
        <mesh
          filename="package://robotuv/meshes/base_link.STL" />
      </geometry>
    </collision>
  </link>


  <link
    name="linkleft">
    <inertial>
      <origin
        xyz="3.172850870925E-08 0.000221252590552168 -7.73712760526735E-11"
        rpy="0 0 0" />
      <mass
        value="0.448182712521403" />
      <inertia
        ixx="0.000398732115195759"
        ixy="-7.20526104896062E-10"
        ixz="-9.60732951326033E-12"
        iyy="0.000597684611816001"
        iyz="-7.24883291603929E-11"
        izz="0.000398732112686358" />
    </inertial>
    <visual>
      <origin
        xyz="0 0 0"
        rpy="0 0 0" />
      <geometry>
        <mesh
          filename="package://robotuv/meshes/linkleft.STL" />
      </geometry>
      <material
        name="">
        <color
          rgba="0.792156862745098 0.819607843137255 0.933333333333333 1" />
      </material>
    </visual>
    <collision>
      <origin
        xyz="0 0 0"
        rpy="0 0 0" />
      <geometry>
        <mesh
          filename="package://robotuv/meshes/linkleft.STL" />
      </geometry>
    </collision>
  </link>
  <joint
    name="leftjoint"
    type="continuous">
    <origin
      xyz="-0.18 0.13645 -0.16"
      rpy="0 0 0" />
    <parent
      link="base_link" />
    <child
      link="linkleft" />
    <axis
      xyz="0 1 0" />
    <limit
      effort="1"
      velocity="1" />
  </joint>


  <link
    name="linkright">
    <inertial>
      <origin
        xyz="-7.00617303062145E-09 -0.000221252590552168 -3.09454001590215E-08"
        rpy="0 0 0" />
      <mass
        value="0.448182712521402" />
      <inertia
        ixx="0.000398732108630963"
        ixy="-2.31476397075009E-10"
        ixz="-8.1041927411806E-12"
        iyy="0.000597684611816"
        iyz="-6.86171336690667E-10"
        izz="0.000398732119251153" />
    </inertial>
    <visual>
      <origin
        xyz="0 0 0"
        rpy="0 0 0" />
      <geometry>
        <mesh
          filename="package://robotuv/meshes/linkright.STL" />
      </geometry>
      <material
        name="">
        <color
          rgba="0.792156862745098 0.819607843137255 0.933333333333333 1" />
      </material>
    </visual>
    <collision>
      <origin
        xyz="0 0 0"
        rpy="0 0 0" />
      <geometry>
        <mesh
          filename="package://robotuv/meshes/linkright.STL" />
      </geometry>
    </collision>
  </link>


  <joint
    name="rightjoint"
    type="continuous">
    <origin
      xyz="-0.185 -0.13645 -0.16"
      rpy="0 0 0" />
    <parent
      link="base_link" />
    <child
      link="linkright" />
    <axis
      xyz="0 -1 0" />
    <limit
      effort="1"
      velocity="1" />
  </joint>
  <link
    name="linkleftcaster">
    <inertial>
      <origin
        xyz="3.46944695195361E-18 1.11022302462516E-16 0.00300279532947036"
        rpy="0 0 0" />
      <mass
        value="0.00899097637518619" />
      <inertia
        ixx="3.95016690231648E-07"
        ixy="4.26825196077363E-23"
        ixz="-2.79183587584397E-23"
        iyy="3.95016690231648E-07"
        iyz="-3.34165120370398E-24"
        izz="5.51492957134569E-07" />
    </inertial>
    <visual>
      <origin
        xyz="0 0 0"
        rpy="0 0 0" />
      <geometry>
        <mesh
          filename="package://robotuv/meshes/linkleftcaster.STL" />
      </geometry>
      <material
        name="">
        <color
          rgba="0.647058823529412 0.619607843137255 0.584313725490196 1" />
      </material>
    </visual>
    <collision>
      <origin
        xyz="0 0 0"
        rpy="0 0 0" />
      <geometry>
        <mesh
          filename="package://robotuv/meshes/linkleftcaster.STL" />
      </geometry>
    </collision>
  </link>


  <joint
    name="leftcasterjoint"
    type="continuous">
    <origin
      xyz="0.2 0.1 -0.2085"
      rpy="0 0 0" />
    <parent
      link="base_link" />
    <child
      link="linkleftcaster" />
    <axis
      xyz="0 0 1" />
    <limit
      effort="1"
      velocity="1" />
  </joint>
  <link
    name="linkrightcaster">
    <inertial>
      <origin
        xyz="3.46944695195361E-18 0 0.00300279532947036"
        rpy="0 0 0" />
      <mass
        value="0.00899097637518619" />
      <inertia
        ixx="3.95016690231648E-07"
        ixy="-2.36849382061017E-23"
        ixz="-2.72717313801967E-23"
        iyy="3.95016690231648E-07"
        iyz="9.70558585395553E-24"
        izz="5.51492957134569E-07" />
    </inertial>
    <visual>
      <origin
        xyz="0 0 0"
        rpy="0 0 0" />
      <geometry>
        <mesh
          filename="package://robotuv/meshes/linkrightcaster.STL" />
      </geometry>
      <material
        name="">
        <color
          rgba="0.647058823529412 0.619607843137255 0.584313725490196 1" />
      </material>
    </visual>
    <collision>
      <origin
        xyz="0 0 0"
        rpy="0 0 0" />
      <geometry>
        <mesh
          filename="package://robotuv/meshes/linkrightcaster.STL" />
      </geometry>
    </collision>
  </link>
  <joint
    name="rightcasterjoint"
    type="continuous">
    <origin
      xyz="0.2 -0.1 -0.2085"
      rpy="0 0 0" />
    <parent
      link="base_link" />
    <child
      link="linkrightcaster" />
    <axis
      xyz="0 0 1" />
    <limit
      effort="1"
      velocity="1" />
  </joint>

  <!--<joint name="imu" type="fixed">
    <parent link="base_link"/>
    <child link="imu"/>
    <origin xyz="0.0 0 0.0" rpy="0 0 0"/>
  </joint>
  <link name="imu"/>-->


 <joint name="scan_joint" type="fixed">
    <parent link="base_link"/>
    <child link="scan"/>
    <origin xyz="0 0 0.0" rpy="0 0 0"/>
  </joint>

  <link name="scan">
    <visual>
      <origin xyz="0.0 0 0.0" rpy="0 0 0"/>
      <geometry>
        <mesh filename="package://robotuv/meshes/lds.stl" scale="0.001 0.001 0.001"/>
      </geometry>
      <material name="dark"/>
    </visual>

    <collision>
      <origin xyz="0.0 0 0.0" rpy="0 0 0"/>
      <geometry>
        <cylinder length="0.0315" radius="0.055"/>
      </geometry>
    </collision>

    <inertial>
      <mass value="0.114" />
      <origin xyz="0 0 0" />
      <inertia ixx="0.001" ixy="0.0" ixz="0.0"
               iyy="0.001" iyz="0.0"
               izz="0.001" />
    </inertial>
  </link>

</robot>